data/sample_head.csv
type,side,price,size,ts_ns
snapshot,b,65863.63,0.00961708,1784618834527258500
snapshot,b,65862.40,0.00153174,1784618834527258500
snapshot,b,65862.31,0.01518320,1784618834527258500
snapshot,b,65861.98,0.00531400,1784618834527258500
snapshot,b,65861.13,0.00163700,1784618834527258500
snapshot,b,65860.51,0.61818317,1784618834527258500
snapshot,b,65860.50,1.00000000,1784618834527258500
snapshot,b,65860.14,0.00030002,1784618834527258500
snapshot,b,65860.00,0.02070000,1784618834527258500
snapshot,b,65859.92,0.00001700,1784618834527258500
snapshot,b,65859.76,0.00664251,1784618834527258500
snapshot,b,65859.72,0.00782317,1784618834527258500
snapshot,b,65859.20,0.00153174,1784618834527258500
snapshot,b,65859.03,0.26680634,1784618834527258500
snapshot,b,65859.02,0.09103615,1784618834527258500
snapshot,b,65858.69,0.01518402,1784618834527258500
snapshot,b,65858.38,0.12147275,1784618834527258500
snapshot,b,65858.30,0.02239100,1784618834527258500
snapshot,b,65858.20,0.00005255,1784618834527258500
snapshot,b,65858.00,0.01070000,1784618834527258500
snapshot,b,65857.18,0.10000000,1784618834527258500
snapshot,b,65857.04,0.01518440,1784618834527258500
snapshot,b,65856.53,0.09103615,1784618834527258500
snapshot,b,65856.21,0.00001700,1784618834527258500
snapshot,b,65856.00,0.00153174,1784618834527258500
snapshot,b,65855.94,0.19350468,1784618834527258500
snapshot,b,65855.92,0.06831285,1784618834527258500
snapshot,b,65855.91,0.39060971,1784618834527258500
snapshot,b,65855.90,0.15699471,1784618834527258500
snapshot,b,65855.57,0.00010510,1784618834527258500
snapshot,b,65855.00,0.01000000,1784618834527258500
snapshot,b,65854.72,0.15184938,1784618834527258500
snapshot,b,65854.51,0.09103615,1784618834527258500
snapshot,b,65853.77,0.01518446,1784618834527258500
snapshot,b,65853.60,0.04555578,1784618834527258500
snapshot,b,65853.59,0.13699998,1784618834527258500
snapshot,b,65853.57,0.04593344,1784618834527258500
snapshot,b,65853.10,0.05000000,1784618834527258500
snapshot,b,65852.82,0.04781787,1784618834527258500
snapshot,b,65852.80,0.00153174,1784618834527258500
snapshot,b,65852.50,0.00001700,1784618834527258500
snapshot,b,65852.33,0.18712194,1784618834527258500
snapshot,b,65852.03,0.09103615,1784618834527258500
snapshot,b,65850.82,0.00758612,1784618834527258500
snapshot,b,65850.81,0.14496190,1784618834527258500
snapshot,b,65850.73,0.02070338,1784618834527258500
snapshot,b,65850.71,0.00021020,1784618834527258500
snapshot,b,65850.44,0.00015185,1784618834527258500
snapshot,b,65850.00,0.01754810,1784618834527258500
snapshot,b,65849.96,0.09103615,1784618834527258500
snapshot,b,65849.60,0.00153174,1784618834527258500
snapshot,b,65849.23,0.16524078,1784618834527258500
snapshot,b,65848.80,0.00034774,1784618834527258500
snapshot,b,65848.79,0.00001700,1784618834527258500
snapshot,b,65848.57,0.00075914,1784618834527258500
snapshot,b,65847.63,0.09103615,1784618834527258500
snapshot,b,65847.62,0.06831285,1784618834527258500
snapshot,b,65847.57,0.00583000,1784618834527258500
snapshot,b,65847.34,0.11721455,1784618834527258500
snapshot,b,65847.17,0.04555578,1784618834527258500
snapshot,b,65847.05,0.02914719,1784618834527258500
snapshot,b,65846.98,0.00121444,1784618834527258500
snapshot,b,65846.65,0.03390659,1784618834527258500
snapshot,b,65846.58,0.00607472,1784618834527258500
snapshot,b,65846.56,0.00030372,1784618834527258500
snapshot,b,65846.40,0.00153174,1784618834527258500
snapshot,b,65846.33,0.00607475,1784618834527258500
snapshot,b,65845.94,0.15141176,1784618834527258500
snapshot,b,65845.35,0.09103615,1784618834527258500
snapshot,b,65845.08,0.00001700,1784618834527258500
snapshot,b,65845.00,0.01000000,1784618834527258500
snapshot,b,65843.98,0.06000000,1784618834527258500
snapshot,b,65843.35,0.09103615,1784618834527258500
snapshot,b,65843.20,0.00153174,1784618834527258500
snapshot,b,65842.66,0.00002277,1784618834527258500
snapshot,b,65841.87,0.00139096,1784618834527258500
snapshot,b,65841.81,0.00019744,1784618834527258500
snapshot,b,65841.73,0.00015187,1784618834527258500
snapshot,b,65841.68,0.11386863,1784618834527258500
snapshot,b,65841.37,0.00001700,1784618834527258500
snapshot,b,65841.31,0.09103615,1784618834527258500
snapshot,b,65840.98,0.00278192,1784618834527258500
snapshot,b,65840.82,0.00042040,1784618834527258500
snapshot,b,65840.69,0.00607527,1784618834527258500
snapshot,b,65840.60,0.05000000,1784618834527258500
snapshot,b,65840.06,0.10858460,1784618834527258500
snapshot,b,65840.00,0.01153174,1784618834527258500
snapshot,b,65839.81,0.06693825,1784618834527258500
snapshot,b,65838.92,0.00607543,1784618834527258500
snapshot,b,65837.66,0.00001700,1784618834527258500
snapshot,b,65836.80,0.00153174,1784618834527258500
snapshot,b,65836.43,0.91309049,1784618834527258500
snapshot,b,65836.34,0.63771757,1784618834527258500
snapshot,b,65836.30,0.23839163,1784618834527258500
snapshot,b,65835.98,0.53123100,1784618834527258500
snapshot,b,65835.95,0.04555294,1784618834527258500
snapshot,b,65835.00,0.01000000,1784618834527258500
snapshot,b,65833.95,0.00001700,1784618834527258500
snapshot,b,65833.62,0.06831285,1784618834527258500
snapshot,b,65833.60,0.00153174,1784618834527258500
snapshot,b,65832.86,0.00102484,1784618834527258500
snapshot,b,65830.51,0.62682117,1784618834527258500
snapshot,b,65830.42,0.50000000,1784618834527258500
snapshot,b,65830.40,0.00153174,1784618834527258500
snapshot,b,65830.24,0.00001700,1784618834527258500
snapshot,b,65830.00,0.01003126,1784618834527258500
snapshot,b,65829.82,0.06597149,1784618834527258500
snapshot,b,65829.17,0.00010505,1784618834527258500
snapshot,b,65828.85,0.06318370,1784618834527258500
snapshot,b,65828.84,0.02382085,1784618834527258500
snapshot,b,65827.81,0.00607645,1784618834527258500
snapshot,b,65827.80,0.00607646,1784618834527258500
snapshot,b,65827.20,0.00153174,1784618834527258500
snapshot,b,65827.05,0.06831285,1784618834527258500
snapshot,b,65826.87,0.00052550,1784618834527258500
snapshot,b,65826.53,0.00001700,1784618834527258500
snapshot,b,65826.19,0.00347740,1784618834527258500
snapshot,b,65826.14,0.03407955,1784618834527258500
snapshot,b,65826.13,0.04555294,1784618834527258500
snapshot,b,65825.00,0.01000000,1784618834527258500
snapshot,b,65824.97,0.00151728,1784618834527258500
snapshot,b,65824.81,0.02051038,1784618834527258500
snapshot,b,65824.00,0.00153174,1784618834527258500
snapshot,b,65822.90,0.00002277,1784618834527258500
snapshot,b,65822.82,0.00001700,1784618834527258500
snapshot,b,65822.59,0.16570359,1784618834527258500
snapshot,b,65822.58,0.14000000,1784618834527258500
snapshot,b,65820.97,0.03389502,1784618834527258500
snapshot,b,65820.84,0.02382085,1784618834527258500
snapshot,b,65820.83,0.06831285,1784618834527258500
snapshot,b,65820.80,0.00153174,1784618834527258500
snapshot,b,65820.00,0.01000000,1784618834527258500
snapshot,b,65819.11,0.00001700,1784618834527258500
snapshot,b,65818.40,0.00758640,1784618834527258500
snapshot,b,65817.68,0.04555294,1784618834527258500
snapshot,b,65817.65,0.45472045,1784618834527258500
snapshot,b,65817.64,0.26156534,1784618834527258500
snapshot,b,65817.60,0.00153174,1784618834527258500
snapshot,b,65817.59,0.06657832,1784618834527258500
snapshot,b,65816.94,0.00155615,1784618834527258500
snapshot,b,65816.54,0.47259260,1784618834527258500
snapshot,b,65816.21,0.00160341,1784618834527258500
snapshot,b,65816.18,0.00145064,1784618834527258500
snapshot,b,65815.58,0.00075969,1784618834527258500
snapshot,b,65815.40,0.00001700,1784618834527258500
snapshot,b,65815.00,0.01000000,1784618834527258500
snapshot,b,65814.73,0.06831285,1784618834527258500
snapshot,b,65814.72,0.75496784,1784618834527258500
snapshot,b,65814.71,1.26307100,1784618834527258500
snapshot,b,65814.41,0.00075913,1784618834527258500
snapshot,a,65863.64,0.10383974,1784618834527258500
snapshot,a,65864.00,0.01070000,1784618834527258500
snapshot,a,65864.02,0.08249148,1784618834527258500
snapshot,a,65864.03,0.12146236,1784618834527258500
snapshot,a,65864.96,0.01518258,1784618834527258500
snapshot,a,65865.29,0.00531400,1784618834527258500
snapshot,a,65865.60,0.00153174,1784618834527258500
